Workbook

Sheet RESUMEN
A1: MRA | B1: CCGT | C1: Coal | D1: Cogeneration | E1: Energia residual | F1: Fuel | G1: Hydro | H1: Other renewables | I1: Solar PV | J1: Solar Thermal | K1: Wind | L1: Hydro Pump-Turb | M1: Biomass | N1: Grand Total | O1: Supply Share % | P1: Supply GWh 2023 | R1: MRA | S1: Biomass + Cogen | T1: CCGT + Coal | U1: Hydro | V1: Hydro Pump | W1: Solar Thermal | X1: Solar PV | Y1: Wind | Z1: Others | AA1: TOTAL | AD1: MRA | AE1: Others | AF1: Biomass + Cogen | AG1: CCGT + Coal | AH1: Hydro | AI1: Hydro Pump | AJ1: Solar Thermal | AK1: Solar PV | AL1: Wind | AM1: TOTAL
A2: AXPO | B2: =+VLOOKUP($A2,Aux!$A$5:$O$677,COLUMN()-COLUMN($A$1)+1,0) -> 0 | C2: =+VLOOKUP($A2,Aux!$A$5:$O$677,COLUMN()-COLUMN($A$1)+1,0) -> 161.9 | D2: =+VLOOKUP($A2,Aux!$A$5:$O$677,COLUMN()-COLUMN($A$1)+1,0) -> 808.1 | E2: =+VLOOKUP($A2,Aux!$A$5:$O$677,COLUMN()-COLUMN($A$1)+1,0) -> 9.4 | F2: =+VLOOKUP($A2,Aux!$A$5:$O$677,COLUMN()-COLUMN($A$1)+1,0) -> 0 | G2: =+VLOOKUP($A2,Aux!$A$5:$O$677,COLUMN()-COLUMN($A$1)+1,0) -> 364.2 | H2: =+VLOOKUP($A2,Aux!$A$5:$O$677,COLUMN()-COLUMN($A$1)+1,0) -> 184 | I2: =+VLOOKUP($A2,Aux!$A$5:$O$677,COLUMN()-COLUMN($A$1)+1,0) -> 1873.8 | ... N2: =+VLOOKUP($A2,Aux!$A$5:$O$677,COLUMN()-COLUMN($A$1)+1,0) -> 7221.9 | R2: =+A2 -> AXPO | S2: =+M2+D2 -> 883.8 | T2: =+B2+C2 -> 161.9 | U2: =+G2 -> 364.2 | V2: =+L2 -> 0 | W2: =+J2 -> 1010.3 | X2: =+I2 -> 1873.8 | Y2: =+K2 -> 2734.5 | Z2: =+SUM(E2,F2,H2) -> 193.4 | AA2: =+SUM(S2:Z2) -> 7221.9 | AD2: =+AD25 -> IGNIS | AE2: =AE25/10^3 -> 0.0016 | AF2: =AF25/10^3 -> 0.194 | AG2: =AG25/10^3 -> 0.3016 | AH2: =AH25/10^3 -> 0.2151 | AI2: =AI25/10^3 -> 0 | AJ2: =AJ25/10^3 -> 0.0998 | AK2: =AK25/10^3 -> 4.3797 | AL2: =AL25/10^3 -> 2.5478 | AM2: =AM25/10^3 -> 7.7396
A3: ACCIONA | B3: =+VLOOKUP($A3,Aux!$A$5:$O$677,COLUMN()-COLUMN($A$1)+1,0) -> 0 | C3: =+VLOOKUP($A3,Aux!$A$5:$O$677,COLUMN()-COLUMN($A$1)+1,0) -> 0 | D3: =+VLOOKUP($A3,Aux!$A$5:$O$677,COLUMN()-COLUMN($A$1)+1,0) -> 4.6 | E3: =+VLOOKUP($A3,Aux!$A$5:$O$677,COLUMN()-COLUMN($A$1)+1,0) -> 0 | F3: =+VLOOKUP($A3,Aux!$A$5:$O$677,COLUMN()-COLUMN($A$1)+1,0) -> 0 | G3: =+VLOOKUP($A3,Aux!$A$5:$O$677,COLUMN()-COLUMN($A$1)+1,0) -> 242.8 | H3: =+VLOOKUP($A3,Aux!$A$5:$O$677,COLUMN()-COLUMN($A$1)+1,0) -> 0 | I3: =+VLOOKUP($A3,Aux!$A$5:$O$677,COLUMN()-COLUMN($A$1)+1,0) -> 211.1 | ... N3: =+VLOOKUP($A3,Aux!$A$5:$O$677,COLUMN()-COLUMN($A$1)+1,0) -> 4913.9 | R3: =+A3 -> ACCIONA | S3: =+M3+D3 -> 115.7 | T3: =+B3+C3 -> 0 | U3: =+G3 -> 242.8 | V3: =+L3 -> 0 | W3: =+J3 -> 0 | X3: =+I3 -> 211.1 | Y3: =+K3 -> 4344.3 | Z3: =+SUM(E3,F3,H3) -> 0 | AA3: =+SUM(S3:Z3) -> 4913.9 | AD3: =+AD26 -> AXPO | AE3: =AE26/10^3 -> 0.1934 | AF3: =AF26/10^3 -> 0.8838 | AG3: =AG26/10^3 -> 0.1619 | AH3: =AH26/10^3 -> 0.3643 | AI3: =AI26/10^3 -> 0 | AJ3: =AJ26/10^3 -> 1.0103 | AK3: =AK26/10^3 -> 1.7944 | AL3: =AL26/10^3 -> 2.6975 | AM3: =AM26/10^3 -> 7.1056
A4: NEXUS | B4: =+VLOOKUP($A4,Aux!$A$5:$O$677,COLUMN()-COLUMN($A$1)+1,0) -> 0 | C4: =+VLOOKUP($A4,Aux!$A$5:$O$677,COLUMN()-COLUMN($A$1)+1,0) -> 12.1 | D4: =+VLOOKUP($A4,Aux!$A$5:$O$677,COLUMN()-COLUMN($A$1)+1,0) -> 310.7 | E4: =+VLOOKUP($A4,Aux!$A$5:$O$677,COLUMN()-COLUMN($A$1)+1,0) -> 0 | F4: =+VLOOKUP($A4,Aux!$A$5:$O$677,COLUMN()-COLUMN($A$1)+1,0) -> 7.9 | G4: =+VLOOKUP($A4,Aux!$A$5:$O$677,COLUMN()-COLUMN($A$1)+1,0) -> 155.4 | H4: =+VLOOKUP($A4,Aux!$A$5:$O$677,COLUMN()-COLUMN($A$1)+1,0) -> 41.7 | I4: =+VLOOKUP($A4,Aux!$A$5:$O$677,COLUMN()-COLUMN($A$1)+1,0) -> 4576.6 | ... N4: =+VLOOKUP($A4,Aux!$A$5:$O$677,COLUMN()-COLUMN($A$1)+1,0) -> 6518.7 | R4: =+A4 -> NEXUS | S4: =+M4+D4 -> 427.4 | T4: =+B4+C4 -> 12.1 | U4: =+G4 -> 155.4 | V4: =+L4 -> 0 | W4: =+J4 -> 249.5 | X4: =+I4 -> 4576.6 | Y4: =+K4 -> 1048.1 | Z4: =+SUM(E4,F4,H4) -> 49.6 | AA4: =+SUM(S4:Z4) -> 6518.7 | AD4: =+AD27 -> NEXUS | AE4: =AE27/10^3 -> 0.0496 | AF4: =AF27/10^3 -> 0.4274 | AG4: =AG27/10^3 -> 0.0121 | AH4: =AH27/10^3 -> 0.1424 | AI4: =AI27/10^3 -> 0 | AJ4: =AJ27/10^3 -> 0.2495 | AK4: =AK27/10^3 -> 4.6002 | AL4: =AL27/10^3 -> 1.0481 | AM4: =AM27/10^3 -> 6.5293
A5: REPSOL | B5: =+VLOOKUP($A5,Aux!$A$5:$O$677,COLUMN()-COLUMN($A$1)+1,0) -> 1624.8 | C5: =+VLOOKUP($A5,Aux!$A$5:$O$677,COLUMN()-COLUMN($A$1)+1,0) -> 225.1 | D5: =+VLOOKUP($A5,Aux!$A$5:$O$677,COLUMN()-COLUMN($A$1)+1,0) -> 494.7 | E5: =+VLOOKUP($A5,Aux!$A$5:$O$677,COLUMN()-COLUMN($A$1)+1,0) -> 0 | F5: =+VLOOKUP($A5,Aux!$A$5:$O$677,COLUMN()-COLUMN($A$1)+1,0) -> 0 | G5: =+VLOOKUP($A5,Aux!$A$5:$O$677,COLUMN()-COLUMN($A$1)+1,0) -> 333.8 | H5: =+VLOOKUP($A5,Aux!$A$5:$O$677,COLUMN()-COLUMN($A$1)+1,0) -> 12.2 | I5: =+VLOOKUP($A5,Aux!$A$5:$O$677,COLUMN()-COLUMN($A$1)+1,0) -> 746.9 | ... N5: =+VLOOKUP($A5,Aux!$A$5:$O$677,COLUMN()-COLUMN($A$1)+1,0) -> 5231.8 | R5: =+A5 -> REPSOL | S5: =+M5+D5 -> 494.7 | T5: =+B5+C5 -> 1849.9 | U5: =+G5 -> 333.8 | V5: =+L5 -> 360.4 | W5: =+J5 -> 0 | X5: =+I5 -> 746.9 | Y5: =+K5 -> 1433.9 | Z5: =+SUM(E5,F5,H5) -> 12.2 | AA5: =+SUM(S5:Z5) -> 5231.8 | AD5: =+AD28 -> REPSOL | AE5: =AE28/10^3 -> 0.0122 | AF5: =AF28/10^3 -> 0.4947 | AG5: =AG28/10^3 -> 1.8499 | AH5: =AH28/10^3 -> 0.3338 | AI5: =AI28/10^3 -> 0.3604 | AJ5: =AJ28/10^3 -> 0 | AK5: =AK28/10^3 -> 0.7469 | AL5: =AL28/10^3 -> 1.4339 | AM5: =AM28/10^3 -> 5.2318
A6: ENGIE | B6: =+VLOOKUP($A6,Aux!$A$5:$O$677,COLUMN()-COLUMN($A$1)+1,0) -> 1989.7 | C6: =+VLOOKUP($A6,Aux!$A$5:$O$677,COLUMN()-COLUMN($A$1)+1,0) -> 0 | D6: =+VLOOKUP($A6,Aux!$A$5:$O$677,COLUMN()-COLUMN($A$1)+1,0) -> 34.3 | E6: =+VLOOKUP($A6,Aux!$A$5:$O$677,COLUMN()-COLUMN($A$1)+1,0) -> 0 | F6: =+VLOOKUP($A6,Aux!$A$5:$O$677,COLUMN()-COLUMN($A$1)+1,0) -> 0 | G6: =+VLOOKUP($A6,Aux!$A$5:$O$677,COLUMN()-COLUMN($A$1)+1,0) -> 77.3 | H6: =+VLOOKUP($A6,Aux!$A$5:$O$677,COLUMN()-COLUMN($A$1)+1,0) -> 0 | I6: =+VLOOKUP($A6,Aux!$A$5:$O$677,COLUMN()-COLUMN($A$1)+1,0) -> 177 | ... N6: =+VLOOKUP($A6,Aux!$A$5:$O$677,COLUMN()-COLUMN($A$1)+1,0) -> 3686.2 | R6: =+A6 -> ENGIE | S6: =+M6+D6 -> 34.3 | T6: =+B6+C6 -> 1989.7 | U6: =+G6 -> 77.3 | V6: =+L6 -> 0 | W6: =+J6 -> 0 | X6: =+I6 -> 177 | Y6: =+K6 -> 1407.9 | Z6: =+SUM(E6,F6,H6) -> 0 | AA6: =+SUM(S6:Z6) -> 3686.2 | AD6: =+AD29 -> GNERA | AE6: =AE29/10^3 -> 0.0259 | AF6: =AF29/10^3 -> 0.2164 | AG6: =AG29/10^3 -> 0.0092 | AH6: =AH29/10^3 -> 0.2487 | AI6: =AI29/10^3 -> 0 | AJ6: =AJ29/10^3 -> 0.3669 | AK6: =AK29/10^3 -> 3.4018 | AL6: =AL29/10^3 -> 0.6784 | AM6: =AM29/10^3 -> 4.9473
A7: IGNIS | B7: =+VLOOKUP($A7,Aux!$A$5:$O$677,COLUMN()-COLUMN($A$1)+1,0) -> 274.6 | C7: =+VLOOKUP($A7,Aux!$A$5:$O$677,COLUMN()-COLUMN($A$1)+1,0) -> 27 | D7: =+VLOOKUP($A7,Aux!$A$5:$O$677,COLUMN()-COLUMN($A$1)+1,0) -> 185.8 | E7: =+VLOOKUP($A7,Aux!$A$5:$O$677,COLUMN()-COLUMN($A$1)+1,0) -> 0 | F7: =+VLOOKUP($A7,Aux!$A$5:$O$677,COLUMN()-COLUMN($A$1)+1,0) -> 0 | G7: =+VLOOKUP($A7,Aux!$A$5:$O$677,COLUMN()-COLUMN($A$1)+1,0) -> 215.1 | H7: =+VLOOKUP($A7,Aux!$A$5:$O$677,COLUMN()-COLUMN($A$1)+1,0) -> 1.6 | I7: =+VLOOKUP($A7,Aux!$A$5:$O$677,COLUMN()-COLUMN($A$1)+1,0) -> 4650.2 | ... N7: =+VLOOKUP($A7,Aux!$A$5:$O$677,COLUMN()-COLUMN($A$1)+1,0) -> 8010.1 | R7: =+A7 -> IGNIS | S7: =+M7+D7 -> 194 | T7: =+B7+C7 -> 301.6 | U7: =+G7 -> 215.1 | V7: =+L7 -> 0 | W7: =+J7 -> 99.8 | X7: =+I7 -> 4650.2 | Y7: =+K7 -> 2547.8 | Z7: =+SUM(E7,F7,H7) -> 1.6 | AA7: =+SUM(S7:Z7) -> 8010.1 | AD7: =+AD30 -> ACCIONA | AE7: =AE30/10^3 -> 0 | AF7: =AF30/10^3 -> 0.1157 | AG7: =AG30/10^3 -> 0 | AH7: =AH30/10^3 -> 0.2428 | AI7: =AI30/10^3 -> 0 | AJ7: =AJ30/10^3 -> 0 | AK7: =AK30/10^3 -> 0.2111 | AL7: =AL30/10^3 -> 4.3443 | AM7: =AM30/10^3 -> 4.9139
A8: GNERA | B8: =+VLOOKUP($A8,Aux!$A$5:$O$677,COLUMN()-COLUMN($A$1)+1,0) -> 0 | C8: =+VLOOKUP($A8,Aux!$A$5:$O$677,COLUMN()-COLUMN($A$1)+1,0) -> 9.2 | D8: =+VLOOKUP($A8,Aux!$A$5:$O$677,COLUMN()-COLUMN($A$1)+1,0) -> 189.7 | E8: =+VLOOKUP($A8,Aux!$A$5:$O$677,COLUMN()-COLUMN($A$1)+1,0) -> 0 | F8: =+VLOOKUP($A8,Aux!$A$5:$O$677,COLUMN()-COLUMN($A$1)+1,0) -> 0 | G8: =+VLOOKUP($A8,Aux!$A$5:$O$677,COLUMN()-COLUMN($A$1)+1,0) -> 248.7 | H8: =+VLOOKUP($A8,Aux!$A$5:$O$677,COLUMN()-COLUMN($A$1)+1,0) -> 25.9 | I8: =+VLOOKUP($A8,Aux!$A$5:$O$677,COLUMN()-COLUMN($A$1)+1,0) -> 3450.3 | ... N8: =+VLOOKUP($A8,Aux!$A$5:$O$677,COLUMN()-COLUMN($A$1)+1,0) -> 5020.8 | R8: =+A8 -> GNERA | S8: =+M8+D8 -> 216.4 | T8: =+B8+C8 -> 9.2 | U8: =+G8 -> 248.7 | V8: =+L8 -> 0 | W8: =+J8 -> 366.9 | X8: =+I8 -> 3450.3 | Y8: =+K8 -> 703.4 | Z8: =+SUM(E8,F8,H8) -> 25.9 | AA8: =+SUM(S8:Z8) -> 5020.8 | AD8: =+AD31 -> ENGIE | AE8: =AE31/10^3 -> 0 | AF8: =AF31/10^3 -> 0.0343 | AG8: =AG31/10^3 -> 1.9897 | AH8: =AH31/10^3 -> 0.0773 | AI8: =AI31/10^3 -> 0 | AJ8: =AJ31/10^3 -> 0 | AK8: =AK31/10^3 -> 0.177 | AL8: =AL31/10^3 -> 1.4111 | AM8: =AM31/10^3 -> 3.6894
A9: ENERGYA | B9: =+VLOOKUP($A9,Aux!$A$5:$O$677,COLUMN()-COLUMN($A$1)+1,0) -> 0 | C9: =+VLOOKUP($A9,Aux!$A$5:$O$677,COLUMN()-COLUMN($A$1)+1,0) -> 53 | D9: =+VLOOKUP($A9,Aux!$A$5:$O$677,COLUMN()-COLUMN($A$1)+1,0) -> 194.8 | E9: =+VLOOKUP($A9,Aux!$A$5:$O$677,COLUMN()-COLUMN($A$1)+1,0) -> 0 | F9: =+VLOOKUP($A9,Aux!$A$5:$O$677,COLUMN()-COLUMN($A$1)+1,0) -> 0 | G9: =+VLOOKUP($A9,Aux!$A$5:$O$677,COLUMN()-COLUMN($A$1)+1,0) -> 140.3 | H9: =+VLOOKUP($A9,Aux!$A$5:$O$677,COLUMN()-COLUMN($A$1)+1,0) -> 26.1 | I9: =+VLOOKUP($A9,Aux!$A$5:$O$677,COLUMN()-COLUMN($A$1)+1,0) -> 1175.6 | ... N9: =+VLOOKUP($A9,Aux!$A$5:$O$677,COLUMN()-COLUMN($A$1)+1,0) -> 2308.5 | R9: =+A9 -> ENERGYA | S9: =+M9+D9 -> 220.3 | T9: =+B9+C9 -> 53 | U9: =+G9 -> 140.3 | V9: =+L9 -> 0 | W9: =+J9 -> 0 | X9: =+I9 -> 1175.6 | Y9: =+K9 -> 693.2 | Z9: =+SUM(E9,F9,H9) -> 26.1 | AA9: =+SUM(S9:Z9) -> 2308.5 | AD9: =+AD32 -> GESTERNOVA | AE9: =AE32/10^3 -> 0.0018 | AF9: =AF32/10^3 -> 0.0022 | AG9: =AG32/10^3 -> 0 | AH9: =AH32/10^3 -> 0.0466 | AI9: =AI32/10^3 -> 0 | AJ9: =AJ32/10^3 -> 0.2702 | AK9: =AK32/10^3 -> 2.6078 | AL9: =AL32/10^3 -> 0.2245 | AM9: =AM32/10^3 -> 3.1531
A10: W2M | B10: =+VLOOKUP($A10,Aux!$A$5:$O$677,COLUMN()-COLUMN($A$1)+1,0) -> 0 | C10: =+VLOOKUP($A10,Aux!$A$5:$O$677,COLUMN()-COLUMN($A$1)+1,0) -> 39.5 | D10: =+VLOOKUP($A10,Aux!$A$5:$O$677,COLUMN()-COLUMN($A$1)+1,0) -> 130.9 | E10: =+VLOOKUP($A10,Aux!$A$5:$O$677,COLUMN()-COLUMN($A$1)+1,0) -> 0 | F10: =+VLOOKUP($A10,Aux!$A$5:$O$677,COLUMN()-COLUMN($A$1)+1,0) -> 0 | G10: =+VLOOKUP($A10,Aux!$A$5:$O$677,COLUMN()-COLUMN($A$1)+1,0) -> 63.7 | H10: =+VLOOKUP($A10,Aux!$A$5:$O$677,COLUMN()-COLUMN($A$1)+1,0) -> 156.1 | I10: =+VLOOKUP($A10,Aux!$A$5:$O$677,COLUMN()-COLUMN($A$1)+1,0) -> 792.4 | ... N10: =+VLOOKUP($A10,Aux!$A$5:$O$677,COLUMN()-COLUMN($A$1)+1,0) -> 2515.7 | R10: =+A10 -> W2M | S10: =+M10+D10 -> 139.1 | T10: =+B10+C10 -> 39.5 | U10: =+G10 -> 63.7 | V10: =+L10 -> 0 | W10: =+J10 -> 0 | X10: =+I10 -> 792.4 | Y10: =+K10 -> 1324.9 | Z10: =+SUM(E10,F10,H10) -> 156.1 | AA10: =+SUM(S10:Z10) -> 2515.7 | AD10: =+AD33 -> ENERGYA | AE10: =AE33/10^3 -> 0.0261 | AF10: =AF33/10^3 -> 0.2266 | AG10: =AG33/10^3 -> 0.053 | AH10: =AH33/10^3 -> 0.1403 | AI10: =AI33/10^3 -> 0 | AJ10: =AJ33/10^3 -> 0.0998 | AK10: =AK33/10^3 -> 1.141 | AL10: =AL33/10^3 -> 1.0656 | AM10: =AM33/10^3 -> 2.7524
A11: ALPIQ | B11: =+VLOOKUP($A11,Aux!$A$5:$O$677,COLUMN()-COLUMN($A$1)+1,0) -> 414 | C11: =+VLOOKUP($A11,Aux!$A$5:$O$677,COLUMN()-COLUMN($A$1)+1,0) -> 0 | D11: =+VLOOKUP($A11,Aux!$A$5:$O$677,COLUMN()-COLUMN($A$1)+1,0) -> 91.9 | E11: =+VLOOKUP($A11,Aux!$A$5:$O$677,COLUMN()-COLUMN($A$1)+1,0) -> 0 | F11: =+VLOOKUP($A11,Aux!$A$5:$O$677,COLUMN()-COLUMN($A$1)+1,0) -> 0 | G11: =+VLOOKUP($A11,Aux!$A$5:$O$677,COLUMN()-COLUMN($A$1)+1,0) -> 0 | H11: =+VLOOKUP($A11,Aux!$A$5:$O$677,COLUMN()-COLUMN($A$1)+1,0) -> 0 | I11: =+VLOOKUP($A11,Aux!$A$5:$O$677,COLUMN()-COLUMN($A$1)+1,0) -> 1102.7 | ... N11: =+VLOOKUP($A11,Aux!$A$5:$O$677,COLUMN()-COLUMN($A$1)+1,0) -> 2431.2 | R11: =+A11 -> ALPIQ | S11: =+M11+D11 -> 91.9 | T11: =+B11+C11 -> 414 | U11: =+G11 -> 0 | V11: =+L11 -> 0 | W11: =+J11 -> 0 | X11: =+I11 -> 1102.7 | Y11: =+K11 -> 822.6 | Z11: =+SUM(E11,F11,H11) -> 0 | AA11: =+SUM(S11:Z11) -> 2431.2 | AD11: =+AD34 -> W2M | AE11: =AE34/10^3 -> 0.1561 | AF11: =AF34/10^3 -> 0.1391 | AG11: =AG34/10^3 -> 0.0395 | AH11: =AH34/10^3 -> 0.0637 | AI11: =AI34/10^3 -> 0 | AJ11: =AJ34/10^3 -> 0 | AK11: =AK34/10^3 -> 0.7924 | AL11: =AL34/10^3 -> 1.2683 | AM11: =AM34/10^3 -> 2.4591
A12: GESTERNOVA | B12: =+VLOOKUP($A12,Aux!$A$5:$O$677,COLUMN()-COLUMN($A$1)+1,0) -> 0 | C12: =+VLOOKUP($A12,Aux!$A$5:$O$677,COLUMN()-COLUMN($A$1)+1,0) -> 0 | D12: =+VLOOKUP($A12,Aux!$A$5:$O$677,COLUMN()-COLUMN($A$1)+1,0) -> 0 | E12: =+VLOOKUP($A12,Aux!$A$5:$O$677,COLUMN()-COLUMN($A$1)+1,0) -> 0 | F12: =+VLOOKUP($A12,Aux!$A$5:$O$677,COLUMN()-COLUMN($A$1)+1,0) -> 0 | G12: =+VLOOKUP($A12,Aux!$A$5:$O$677,COLUMN()-COLUMN($A$1)+1,0) -> 46.6 | H12: =+VLOOKUP($A12,Aux!$A$5:$O$677,COLUMN()-COLUMN($A$1)+1,0) -> 1.8 | I12: =+VLOOKUP($A12,Aux!$A$5:$O$677,COLUMN()-COLUMN($A$1)+1,0) -> 2612.2 | ... N12: =+VLOOKUP($A12,Aux!$A$5:$O$677,COLUMN()-COLUMN($A$1)+1,0) -> 3314.9 | R12: =+A12 -> GESTERNOVA | S12: =+M12+D12 -> 2.2 | T12: =+B12+C12 -> 0 | U12: =+G12 -> 46.6 | V12: =+L12 -> 0 | W12: =+J12 -> 320.1 | X12: =+I12 -> 2612.2 | Y12: =+K12 -> 332 | Z12: =+SUM(E12,F12,H12) -> 1.8 | AA12: =+SUM(S12:Z12) -> 3314.9 | AD12: =+AD35 -> ALPIQ | AE12: =AE35/10^3 -> 0 | AF12: =AF35/10^3 -> 0.0919 | AG12: =AG35/10^3 -> 0.414 | AH12: =AH35/10^3 -> 0 | AI12: =AI35/10^3 -> 0 | AJ12: =AJ35/10^3 -> 0 | AK12: =AK35/10^3 -> 1.0831 | AL12: =AL35/10^3 -> 0.8217 | AM12: =AM35/10^3 -> 2.4107
A13: HOLALUZ | B13: =+VLOOKUP($A13,Aux!$A$5:$O$677,COLUMN()-COLUMN($A$1)+1,0) -> 0 | C13: =+VLOOKUP($A13,Aux!$A$5:$O$677,COLUMN()-COLUMN($A$1)+1,0) -> 0 | D13: =+VLOOKUP($A13,Aux!$A$5:$O$677,COLUMN()-COLUMN($A$1)+1,0) -> 22.8 | E13: =+VLOOKUP($A13,Aux!$A$5:$O$677,COLUMN()-COLUMN($A$1)+1,0) -> 0 | F13: =+VLOOKUP($A13,Aux!$A$5:$O$677,COLUMN()-COLUMN($A$1)+1,0) -> 0 | G13: =+VLOOKUP($A13,Aux!$A$5:$O$677,COLUMN()-COLUMN($A$1)+1,0) -> 0 | H13: =+VLOOKUP($A13,Aux!$A$5:$O$677,COLUMN()-COLUMN($A$1)+1,0) -> 0 | I13: =+VLOOKUP($A13,Aux!$A$5:$O$677,COLUMN()-COLUMN($A$1)+1,0) -> 256.5 | ... N13: =+VLOOKUP($A13,Aux!$A$5:$O$677,COLUMN()-COLUMN($A$1)+1,0) -> 279.3 | R13: =+A13 -> HOLALUZ | S13: =+M13+D13 -> 22.8 | T13: =+B13+C13 -> 0 | U13: =+G13 -> 0 | V13: =+L13 -> 0 | W13: =+J13 -> 0 | X13: =+I13 -> 256.5 | Y13: =+K13 -> 0 | Z13: =+SUM(E13,F13,H13) -> 0 | AA13: =+SUM(S13:Z13) -> 279.3 | AD13: =+AD36 -> GALP | AE13: =AE36/10^3 -> 0 | AF13: =AF36/10^3 -> 0 | AG13: =AG36/10^3 -> 0 | AH13: =AH36/10^3 -> 0 | AI13: =AI36/10^3 -> 0 | AJ13: =AJ36/10^3 -> 0.1498 | AK13: =AK36/10^3 -> 1.4169 | AL13: =AL36/10^3 -> 0.1605 | AM13: =AM36/10^3 -> 1.7272
... A16: GALP | B16: =+VLOOKUP($A16,Aux!$A$5:$O$677,COLUMN()-COLUMN($A$1)+1,0) -> 0 | C16: =+VLOOKUP($A16,Aux!$A$5:$O$677,COLUMN()-COLUMN($A$1)+1,0) -> 0 | D16: =+VLOOKUP($A16,Aux!$A$5:$O$677,COLUMN()-COLUMN($A$1)+1,0) -> 0 | E16: =+VLOOKUP($A16,Aux!$A$5:$O$677,COLUMN()-COLUMN($A$1)+1,0) -> 0 | F16: =+VLOOKUP($A16,Aux!$A$5:$O$677,COLUMN()-COLUMN($A$1)+1,0) -> 0 | G16: =+VLOOKUP($A16,Aux!$A$5:$O$677,COLUMN()-COLUMN($A$1)+1,0) -> 0 | H16: =+VLOOKUP($A16,Aux!$A$5:$O$677,COLUMN()-COLUMN($A$1)+1,0) -> 0 | I16: =+VLOOKUP($A16,Aux!$A$5:$O$677,COLUMN()-COLUMN($A$1)+1,0) -> 1416.9 | ... N16: =+VLOOKUP($A16,Aux!$A$5:$O$677,COLUMN()-COLUMN($A$1)+1,0) -> 2027 | R16: =+A16 -> GALP | S16: =+M16+D16 -> 0 | T16: =+B16+C16 -> 0 | U16: =+G16 -> 0 | V16: =+L16 -> 0 | W16: =+J16 -> 199.7 | X16: =+I16 -> 1416.9 | Y16: =+K16 -> 410.4 | Z16: =+SUM(E16,F16,H16) -> 0 | AA16: =+SUM(S16:Z16) -> 2027 | AD16: =+AD39 -> HOLALUZ | AE16: =AE39/10^3 -> 0 | AF16: =AF39/10^3 -> 0.0228 | AG16: =AG39/10^3 -> 0 | AH16: =AH39/10^3 -> 0 | AI16: =AI39/10^3 -> 0 | AJ16: =AJ39/10^3 -> 0 | AK16: =AK39/10^3 -> 0.2569 | AL16: =AL39/10^3 -> 0 | AM16: =AM39/10^3 -> 0.2797
A18: IBERDROLA | B18: =+VLOOKUP($A18,Aux!$A$5:$O$677,COLUMN()-COLUMN($A$1)+1,0) -> 5183.4 | C18: =+VLOOKUP($A18,Aux!$A$5:$O$677,COLUMN()-COLUMN($A$1)+1,0) -> 37.1 | D18: =+VLOOKUP($A18,Aux!$A$5:$O$677,COLUMN()-COLUMN($A$1)+1,0) -> 299.5 | E18: =+VLOOKUP($A18,Aux!$A$5:$O$677,COLUMN()-COLUMN($A$1)+1,0) -> 0 | F18: =+VLOOKUP($A18,Aux!$A$5:$O$677,COLUMN()-COLUMN($A$1)+1,0) -> 0 | G18: =+VLOOKUP($A18,Aux!$A$5:$O$677,COLUMN()-COLUMN($A$1)+1,0) -> 8346.7 | H18: =+VLOOKUP($A18,Aux!$A$5:$O$677,COLUMN()-COLUMN($A$1)+1,0) -> 20.3 | I18: =+VLOOKUP($A18,Aux!$A$5:$O$677,COLUMN()-COLUMN($A$1)+1,0) -> 4125.5 | ... N18: =+VLOOKUP($A18,Aux!$A$5:$O$677,COLUMN()-COLUMN($A$1)+1,0) -> 26068.6 | R18: =+A18 -> IBERDROLA | S18: =+M18+D18 -> 299.5 | T18: =+B18+C18 -> 5220.5 | U18: =+G18 -> 8346.7 | V18: =+L18 -> 1511.7 | W18: =+J18 -> 0 | X18: =+I18 -> 4125.5 | Y18: =+K18 -> 6544.4 | Z18: =+SUM(E18,F18,H18) -> 20.3 | AA18: =+SUM(S18:Z18) -> 26068.6
A19: ENDESA | B19: =+VLOOKUP($A19,Aux!$A$5:$O$677,COLUMN()-COLUMN($A$1)+1,0) -> 2919.2 | C19: =+VLOOKUP($A19,Aux!$A$5:$O$677,COLUMN()-COLUMN($A$1)+1,0) -> 14.5 | D19: =+VLOOKUP($A19,Aux!$A$5:$O$677,COLUMN()-COLUMN($A$1)+1,0) -> 282.9 | E19: =+VLOOKUP($A19,Aux!$A$5:$O$677,COLUMN()-COLUMN($A$1)+1,0) -> 11.5 | F19: =+VLOOKUP($A19,Aux!$A$5:$O$677,COLUMN()-COLUMN($A$1)+1,0) -> 0 | G19: =+VLOOKUP($A19,Aux!$A$5:$O$677,COLUMN()-COLUMN($A$1)+1,0) -> 4014.8 | H19: =+VLOOKUP($A19,Aux!$A$5:$O$677,COLUMN()-COLUMN($A$1)+1,0) -> 0.4 | I19: =+VLOOKUP($A19,Aux!$A$5:$O$677,COLUMN()-COLUMN($A$1)+1,0) -> 2427.1 | ... N19: =+VLOOKUP($A19,Aux!$A$5:$O$677,COLUMN()-COLUMN($A$1)+1,0) -> 13851.1 | R19: =+A19 -> ENDESA | S19: =+M19+D19 -> 290.5 | T19: =+B19+C19 -> 2933.7 | U19: =+G19 -> 4014.8 | V19: =+L19 -> 1330.4 | W19: =+J19 -> 0 | X19: =+I19 -> 2427.1 | Y19: =+K19 -> 2842.7 | Z19: =+SUM(E19,F19,H19) -> 11.9 | AA19: =+SUM(S19:Z19) -> 13851.1
A20: NATURGY | B20: =+VLOOKUP($A20,Aux!$A$5:$O$677,COLUMN()-COLUMN($A$1)+1,0) -> 7295.4 | C20: =+VLOOKUP($A20,Aux!$A$5:$O$677,COLUMN()-COLUMN($A$1)+1,0) -> 0 | D20: =+VLOOKUP($A20,Aux!$A$5:$O$677,COLUMN()-COLUMN($A$1)+1,0) -> 182.2 | E20: =+VLOOKUP($A20,Aux!$A$5:$O$677,COLUMN()-COLUMN($A$1)+1,0) -> 0 | F20: =+VLOOKUP($A20,Aux!$A$5:$O$677,COLUMN()-COLUMN($A$1)+1,0) -> 0 | G20: =+VLOOKUP($A20,Aux!$A$5:$O$677,COLUMN()-COLUMN($A$1)+1,0) -> 1832.2 | H20: =+VLOOKUP($A20,Aux!$A$5:$O$677,COLUMN()-COLUMN($A$1)+1,0) -> 0 | I20: =+VLOOKUP($A20,Aux!$A$5:$O$677,COLUMN()-COLUMN($A$1)+1,0) -> 989.6 | ... N20: =+VLOOKUP($A20,Aux!$A$5:$O$677,COLUMN()-COLUMN($A$1)+1,0) -> 12612.4 | R20: =+A20 -> NATURGY | S20: =+M20+D20 -> 182.2 | T20: =+B20+C20 -> 7295.4 | U20: =+G20 -> 1832.2 | V20: =+L20 -> 215 | W20: =+J20 -> 0 | X20: =+I20 -> 989.6 | Y20: =+K20 -> 2098 | Z20: =+SUM(E20,F20,H20) -> 0 | AA20: =+SUM(S20:Z20) -> 12612.4 | AF20: 1000
A21: EDP | B21: =+VLOOKUP($A21,Aux!$A$5:$O$677,COLUMN()-COLUMN($A$1)+1,0) -> 854.1 | C21: =+VLOOKUP($A21,Aux!$A$5:$O$677,COLUMN()-COLUMN($A$1)+1,0) -> 1257.9 | D21: =+VLOOKUP($A21,Aux!$A$5:$O$677,COLUMN()-COLUMN($A$1)+1,0) -> 10 | E21: =+VLOOKUP($A21,Aux!$A$5:$O$677,COLUMN()-COLUMN($A$1)+1,0) -> 0 | F21: =+VLOOKUP($A21,Aux!$A$5:$O$677,COLUMN()-COLUMN($A$1)+1,0) -> 0 | G21: =+VLOOKUP($A21,Aux!$A$5:$O$677,COLUMN()-COLUMN($A$1)+1,0) -> 450.6 | H21: =+VLOOKUP($A21,Aux!$A$5:$O$677,COLUMN()-COLUMN($A$1)+1,0) -> 0 | I21: =+VLOOKUP($A21,Aux!$A$5:$O$677,COLUMN()-COLUMN($A$1)+1,0) -> 204.4 | ... N21: =+VLOOKUP($A21,Aux!$A$5:$O$677,COLUMN()-COLUMN($A$1)+1,0) -> 4642.1 | R21: =+A21 -> EDP | S21: =+M21+D21 -> 10 | T21: =+B21+C21 -> 2112 | U21: =+G21 -> 450.6 | V21: =+L21 -> 0 | W21: =+J21 -> 0 | X21: =+I21 -> 204.4 | Y21: =+K21 -> 1865.1 | Z21: =+SUM(E21,F21,H21) -> 0 | AA21: =+SUM(S21:Z21) -> 4642.1
AD24: MRA | AE24: Others | AF24: Biomass + Cogen | AG24: CCGT + Coal | AH24: Hydro | AI24: Hydro Pump | AJ24: Solar Thermal | AK24: Solar PV | AL24: Wind | AM24: TOTAL
AD25: IGNIS | AE25: 1.6 | AF25: 194 | AG25: 301.6 | AH25: 215.1 | AI25: 0 | AJ25: 99.8 | AK25: 4379.7 | AL25: 2547.8 | AM25: 7739.6
AD26: AXPO | AE26: 193.4 | AF26: 883.8 | AG26: 161.9 | AH26: 364.3 | AI26: 0 | AJ26: 1010.3 | AK26: 1794.4 | AL26: 2697.5 | AM26: 7105.6
AD27: NEXUS | AE27: 49.6 | AF27: 427.4 | AG27: 12.1 | AH27: 142.4 | AI27: 0 | AJ27: 249.5 | AK27: 4600.2 | AL27: 1048.1 | AM27: 6529.3
AD28: REPSOL | AE28: 12.2 | AF28: 494.7 | AG28: 1849.9 | AH28: 333.8 | AI28: 360.4 | AJ28: 0 | AK28: 746.9 | AL28: 1433.9 | AM28: 5231.8
AD29: GNERA | AE29: 25.9 | AF29: 216.4 | AG29: 9.2 | AH29: 248.7 | AI29: 0 | AJ29: 366.9 | AK29: 3401.8 | AL29: 678.4 | AM29: 4947.3
AD30: ACCIONA | AE30: 0 | AF30: 115.7 | AG30: 0 | AH30: 242.8 | AI30: 0 | AJ30: 0 | AK30: 211.1 | AL30: 4344.3 | AM30: 4913.9
AD31: ENGIE | AE31: 0 | AF31: 34.3 | AG31: 1989.7 | AH31: 77.3 | AI31: 0 | AJ31: 0 | AK31: 177 | AL31: 1411.1 | AM31: 3689.4
AD32: GESTERNOVA | AE32: 1.8 | AF32: 2.2 | AG32: 0 | AH32: 46.6 | AI32: 0 | AJ32: 270.2 | AK32: 2607.8 | AL32: 224.5 | AM32: 3153.1
AD33: ENERGYA | AE33: 26.1 | AF33: 226.6 | AG33: 53 | AH33: 140.3 | AI33: 0 | AJ33: 99.8 | AK33: 1141 | AL33: 1065.6 | AM33: 2752.4
AD34: W2M | AE34: 156.1 | AF34: 139.1 | AG34: 39.5 | AH34: 63.7 | AI34: 0 | AJ34: 0 | AK34: 792.4 | AL34: 1268.3 | AM34: 2459.1
AD35: ALPIQ | AE35: 0 | AF35: 91.9 | AG35: 414 | AH35: 0 | AI35: 0 | AJ35: 0 | AK35: 1083.1 | AL35: 821.7 | AM35: 2410.7
AD36: GALP | AE36: 0 | AF36: 0 | AG36: 0 | AH36: 0 | AI36: 0 | AJ36: 149.8 | AK36: 1416.9 | AL36: 160.5 | AM36: 1727.2
... AD39: HOLALUZ | AE39: 0 | AF39: 22.8 | AG39: 0 | AH39: 0 | AI39: 0 | AJ39: 0 | AK39: 256.9 | AL39: 0 | AM39: 279.7

Sheet Sheet1
A2: Sujeto del Mercado | B2: HOLALUZ
A3: Tipo de UP | B3: Generación
A5: Row Labels | B5: Sum of Power MW
A6: Gas Natural Cogeneración | B6: 22.8
A7: TSEAT | B7: 22.8
A8: Solar fotovoltaica | B8: 256.5
A9: CLIFV10 | B9: 4.3
A10: CLIFV30 | B10: 40.7
A11: CLIFV31 | B11: 40.7
A12: CLIFV32 | B12: 40.2
A13: CLIFV35 | B13: 10
A14: CLIFV45 | B14: 16.8
A15: CLIFV53 | B15: 16.8
A16: CLIFV54 | B16: 22.4
A17: CLIFV55 | B17: 39
... A20: Grand Total | B20: 279.3
B23: =40.7*3 -> 122.1
B24: =+GETPIVOTDATA("Power MW",$A$5)-B23 -> 157.2

Sheet export_unidades-de-programacion
A2: UP | B2: Descrip Short | C2: Descrip Long | D2: Power MW | E2: EIC Code | F2: Tech | G2: Buy-Sell | H2: Regulation Zone | I2: Sujeto del Mercado 2 | J2: Tipo de UP | K2: Sujeto del Mercado | L2: Technologia | M2: RZ
A3: A2GAME2 | B3: A2GAME2 | C3: A2GAME2 | D3: 3.8 | E3: 18W000000000R205 | F3: Energia residual | G3: Venta | H3: SZR | I3: AME | J3: Generación | K3: AGENTE DEL MERCADO ELECTRICO | L3: Energía residual | M3: SZR
A4: ABA1 | B4: ABA1 | C4: ABARAN | D4: 0.3 | E4: 18WABA1-123456-K | F4: Hydro | G4: Venta | H4: SZR | I4: BARER | J4: Generación | K4: BARBO ENERGÃAS RENOVABLES S.A. | L4: Hidráulica UGH | M4: SZR
A5: ABA2 | B5: ABA2 | C5: ABARAN 2 | D5: 0.4 | E5: 18WABA2-123456-A | F5: Hydro | G5: Venta | H5: SZR | I5: BARER | J5: Generación | K5: BARBO ENERGÃAS RENOVABLES S.A. | L5: Hidráulica UGH | M5: SZR
A6: ABASC01 | B6: UPC ABAST | C6: UP COMPRA ABASTE | D6: 1 | E6: 18W000000000G8RE | F6: Supply | G6: Compra | H6: SZR | I6: ABAST | J6: Comercializadores | K6: ABASTE COMERCIALIZADORA | L6: Comercializadores mercado libre | M6: SZR
A7: ABO1 | B7: ABOÑO 1 | C7: C.T. ABOÑO 1 | D7: 341.7 | E7: 18WABO1-12345-0X | F7: Coal | G7: Venta | H7: SZR | I7: ABOGE | J7: Generación | K7: EDP | L7: Hulla antracita | M7: SZR
A8: ABO2G | B8: ABO2G | C8: ABOÑO2 GAS | D8: 561.8 | E8: 18W000000000T2JX | F8: Natural gas | G8: Venta | H8: SZR | I8: ABOGE | J8: Generación | K8: EDP | L8: Gas Natural | M8: SZR
A9: ABOUC01 | B9: ABOUTWHI | C9: ABOUT WHITE, S.L. | D9: 0.1 | E9: 18WABOUC01-123-F | F9: Supply | G9: Compra | H9: SZR | I9: ABOUT | J9: Comercializadores | K9: ABOUT WHITE SL | L9: Comercializadores mercado libre | M9: SZR
A10: ABOX | B10: ABOX | C10: COMPRA SSAA ABOÑO | D10: 30 | E10: 18W000000000R1YE | F10: Consumo de Servicios Auxiliares | G10: Compra | H10: SZR | I10: ABOGE | J10: Servicios auxiliares | K10: EDP | L10: Consumo de Servicios Auxiliares | M10: SZR
A11: ACAPC01 | B11: ACAPERSA | C11: ACAPERSA 1997 | D11: 0.8 | E11: 18W000000000MBVA | F11: Consumos directos en mercado | G11: Compra | H11: SZR | I11: ACAPE | J11: Consum. directos a mercado | K11: ACAPERSA 1997 SL | L11: Consumos directos en mercado | M11: SZR
A12: ACBFRAE | B12: ACBFRA EXP | C12: ACCIÓN COORDINADA DE BALANCE ES A FR | D12: 9999 | E12: 18WACBFRAE-12--2 | F12: Unidad instrumental internacional | G12: Compra | H12: SZR | I12: REE | J12: Unidad instrumental internacional | K12: REE | L12: Unidad instrumental internacional | M12: SZR
A13: ACBFRAI | B13: ACBFRA IMP | C13: ACCIÓN COORDINADA DE BALANCE FR A ES | D13: 9999 | E13: 18WACBFRAI-12--B | F13: Unidad instrumental internacional | G13: Venta | H13: SZR | I13: REE | J13: Unidad instrumental internacional | K13: REE | L13: Unidad instrumental internacional | M13: SZR
A14: ACBPORE | B14: ACBPOR EXP | C14: ACCIÓN COORDINADA DE BALANCE ES A PT | D14: 9999 | E14: 18WACBPORE-123-3 | F14: Unidad instrumental internacional | G14: Compra | H14: SZR | I14: REE | J14: Unidad instrumental internacional | K14: REE | L14: Unidad instrumental internacional | M14: SZR
... A421: DUER | B421: DUERO G | C421: UGH. DUERO GENERACION | D421: 3533.6 | E421: 18WDUER-12345-0N | F421: Hydro | G421: Venta | H421: IBEG | I421: IBEG | J421: Generación | K421: IBERDROLA | L421: Hidráulica UGH | M421: IMA
A422: DUERC01 | B422: DUEROLUZ | C422: DUEROLUZ ENERGIA SL | D422: 1 | E422: 18W000000000TDOR | F422: #N/A | G422: Compra | H422: SZR | I422: DUERO | J422: Comercializadores | K422: DUEROLUZ ENERGIA | M422: SZR
A423: DUFEC01 | B423: DUFEC01 | C423: DUFEC01 | D423: 400 | E423: 18W000000000BEUA | F423: Supply | G423: Compra | H423: SZR | I423: DUFER | J423: Comercializadores | K423: DXT COMMODITIES SA | L423: Comercializadores mercado libre | M423: SZR
A424: DUFECP3 | B424: DUFENERGY | C424: DUFENERGY TRADING SA | D424: 400 | E424: 18WDUFECP3-123-F | F424: Exportacion Francia | G424: Compra | H424: SZR | I424: DUFER | J424: Comercializador internacional | K424: DXT COMMODITIES SA | L424: Exportación Francia | M424: SZR
A425: DUFEVP3 | B425: DUFEVP3 | C425: DUFENERGY TRADING SA | D425: 400 | E425: 18WDUFEVP3-123-T | F425: Importacion Francia | G425: Venta | H425: SZR | I425: DUFER | J425: Comercializador internacional | K425: DXT COMMODITIES SA | L425: Importación Francia | M425: SZR
A426: DXDC01 | B426: DXD COMER | C426: DXD COMERCIALIZADORA UNIDAD | D426: 1 | E426: 18W0000000004U8Y | F426: Supply | G426: Compra | H426: SZR | I426: DXD | J426: Comercializadores | K426: DX COMERCIALIZADORA | L426: Comercializadores mercado libre | M426: SZR
A427: DYNFC01 | B427: DYNEFF | C427: DYNEFF | D427: 0.1 | E427: 18W000000000M1A8 | F427: Supply | G427: Compra | H427: SZR | I427: DYNEF | J427: Comercializadores | K427: DYNEFF ESPAÃ‘A SL | L427: Comercializadores mercado libre | M427: SZR
A428: E1CEG | B428: E1CEG | C428: E1CEG | D428: 26 | E428: 18W0000000003SIO | F428: Wind | G428: Venta | H428: EVM2 | I428: CEG | J428: Generación | K428: ENERGYA | L428: Eólica terrestre | M428: VM2
A429: E1VENTU | B429: E1VENTU | C429: E1VENTU | D429: 20.5 | E429: 18W000000000Q7QG | F429: Wind | G429: Venta | H429: SZR | I429: CEG | J429: Generación | K429: ENERGYA | L429: Eólica terrestre | M429: SZR
A430: EABARA | B430: EABARA | C430: PARQUE EOLICO DE ABARA | D430: 34 | E430: 18WEABARA-1234-J | F430: Wind | G430: Venta | H430: SZR | I430: EGED | J430: Generación | K430: ACCIONA | L430: Eólica terrestre | M430: SZR
A431: EABILI | B431: EABILI | C431: EOL ABLITAS | D431: 40 | E431: 18W000000000IGUD | F431: Wind | G431: Venta | H431: SZR | I431: CEG | J431: Generación | K431: ENERGYA | L431: Eólica terrestre | M431: SZR
A432: EACCIT | B432: EACCIT | C432: 18W000000000NXEB | D432: 3.4 | E432: 18W000000000NXEB | F432: Wind | G432: Venta | H432: SZR | I432: EGLE | J432: Generación | K432: AXPO | L432: Eólica terrestre | M432: SZR
A433: EACIBER | B433: EACIBER | C433: ACIBEROS | D433: 53.6 | E433: 18W000000000RXFU | F433: Wind | G433: Venta | H433: SZR | I433: WMARK | J433: Generación | K433: W2M | L433: Eólica terrestre | M433: SZR
A434: EACROA1 | B434: EACROA1 | C434: UP EOLICA DA CROA1 | D434: 7.3 | E434: 18W000000000N0HU | F434: Wind | G434: Venta | H434: NEXUS | I434: NEXU | J434: Generación | K434: NEXUS | L434: Eólica terrestre | M434: NEX
... A2254: JMFEC01 | B2254: JMFEC01 | C2254: JMFEC01 | D2254: 0.1 | E2254: 18W000000000R0ZF | F2254: Supply | G2254: Compra | H2254: SZR | I2254: JMFEN | J2254: Comercializadores | K2254: JMF ENERGIAS RENOVABLES, S.L | L2254: Comercializadores mercado libre | M2254: SZR
A2255: JOINC01 | B2255: ENERJOIN | C2255: ENERJOIN | D2255: 1101.5 | E2255: 18W00000000022QG | F2255: Consumos directos en mercado | G2255: Compra | H2255: SZR | I2255: JOIN | J2255: Consum. directos a mercado | K2255: 1 | L2255: Consumos directos en mercado | M2255: SZR
A2256: JOLCA | B2256: JOLCA | C2256: JOLCAFV | D2256: 0.3 | E2256: 18W000000000SFY5 | F2256: Solar PV | G2256: Venta | H2256: SZR | I2256: ELEIA | J2256: Generación | K2256: ELECTRICIDAD ELEIA SL | L2256: Solar fotovoltaica | M2256: SZR
A2257: JOSEC01 | B2257: JOSEC01 | C2257: ELECTRICA SUDANDELL | D2257: 0.7 | E2257: 18WJOSECO1-12--B | F2257: Supply | G2257: Compra | H2257: SZR | I2257: JOSEP | J2257: Comercializadores | K2257: ELECTRICA DE SUDANELL SL | L2257: Comercializadores mercado libre | M2257: SZR
A2258: JOVEC01 | B2258: UP JOVE | C2258: UPROGRAMACION JOVE | D2258: 0.1 | E2258: 18W000000000RG7N | F2258: Supply | G2258: Compra | H2258: SZR | I2258: JOVE | J2258: Comercializadores | K2258: JOVE ENERGÍA RENOVABLE SL | L2258: Comercializadores mercado libre | M2258: SZR
A2259: JRONCP3 | B2259: JRONCP3 | C2259: J.ARON EXPORTACIÓN DE ENERGÍA | D2259: 0 | E2259: 18WJRONCP3-123-6 | F2259: Exportacion Francia | G2259: Compra | H2259: SZR | I2259: JARON | J2259: Comercializador internacional | K2259: J.ARON & COMPANY | L2259: Exportación Francia | M2259: SZR
A2260: JRONVP3 | B2260: JRONVP3 | C2260: J.ARON IMPORTACIÓN DE ENERGÍA | D2260: 0 | E2260: 18WJRONVP3-123-K | F2260: Importacion Francia | G2260: Venta | H2260: SZR | I2260: JARON | J2260: Comercializador internacional | K2260: J.ARON & COMPANY | L2260: Importación Francia | M2260: SZR
A2261: JUANC01 | B2261: JUANX_UP | C2261: JUAN_ENERGY_UP | D2261: 0.6 | E2261: 18W000000000IB70 | F2261: Supply | G2261: Compra | H2261: SZR | I2261: JUANX | J2261: Comercializadores | K2261: JUAN ENERGY COMERCIALIZADORA | L2261: Comercializadores mercado libre | M2261: SZR
A2262: JUCA | B2262: JUCAR | C2262: UGH. JUCAR | D2262: 712.7 | E2262: 18WJUCA-12345-0Q | F2262: Hydro | G2262: Venta | H2262: IBEG | I2262: IBEG | J2262: Generación | K2262: IBERDROLA | L2262: Hidráulica UGH | M2262: IMA
A2263: JUCAR2 | B2263: JUCAR2 | C2263: UGH CASTELNOU | D2263: 0.8 | E2263: 18WJUCAR2-1234-Q | F2263: Hydro | G2263: Venta | H2263: SZR | I2263: CTNU | J2263: Generación | K2263: ENGIE | L2263: Hidráulica UGH | M2263: SZR
A2264: JUSEC01 | B2264: JUSEC01 | C2264: JUSEC01 | D2264: 0.1 | E2264: 18W000000000O3US | F2264: Supply | G2264: Compra | H2264: SZR | I2264: JUSEP | J2264: Comercializadores | K2264: JUST ENERGY PRO LUZ | L2264: Comercializadores mercado libre | M2264: SZR
A2265: KARMC01 | B2265: KARMC01 | C2265: KARMA ALIMUR | D2265: 1 | E2265: 18W000000000QDQZ | F2265: Supply | G2265: Compra | H2265: SZR | I2265: KARMA | J2265: Comercializadores | K2265: KARMA ALIMUR S.L. | L2265: Comercializadores mercado libre | M2265: SZR
A2266: KAUNITE | B2266: KAUNITE | C2266: COG. KANUI TEXTIL | D2266: 1.9 | E2266: 18WKAUNITE-12-1D | F2266: Cogeneration | G2266: Venta | H2266: SZR | I2266: KAEN | J2266: Generación | K2266: KANUI ENERGIA | L2266: Gas Natural Cogeneración | M2266: SZR
...

Sheet Aux
A3: Sum of Power MW | B3: Column Labels
A4: Row Labels | B4: CCGT | C4: Coal | D4: Cogeneration | E4: Energia residual | F4: Fuel | G4: Hydro | H4: Other renewables | I4: Solar PV | J4: Solar Thermal | K4: Wind | L4: Hydro Pump-Turb | M4: Biomass | N4: Grand Total
A5: 18XATAL-12345-1E | D5: 12 | N5: 12
A6: 18XBURGE-1234--I | K6: 13.8 | N6: 13.8
A7: 18XMIRAS-12345-9 | K7: 40.9 | N7: 40.9
A8: 18XNEOSC-12345-4 | D8: 9.7 | N8: 9.7
A9: 18XPAPELECKERSAC | D9: 4.8 | N9: 4.8
A10: 18XPEUSA-12345-4 | G10: 9.3 | N10: 9.3
A11: 18XTIRCA-12345-N | H11: 9.9 | N11: 9.9
A12: ACCIONA | D12: 4.6 | G12: 242.8 | I12: 211.1 | K12: 4344.3 | M12: 111.1 | N12: 4913.9
A13: ADEINNOVA ENERGIA S.L | I13: 0.2 | N13: 0.2
A14: AE3000 AGENT COMERCIALIZADOR S | I14: 2.1 | N14: 2.1
A15: AGENTE DEL MERCADO ELECTRICO | D15: 135.8 | E15: 23.1 | G15: 5.5 | H15: 11.5 | I15: 1.1 | N15: 177
A16: AGRI ENERGIA, S. A. | G16: 1.2 | I16: 0.2 | N16: 1.4
A17: ALDROENERGIA Y SOLUCIONES SL | I17: 47.3 | N17: 47.3
A18: ASISTENCIA ENERGÃ‰TICA S.L. | G18: 75.3 | I18: 41.2 | N18: 116.5
A19: ATENCO ENERGIA | I19: 14.3 | N19: 14.3
A20: ATLAS ENERGIA COMERCIAL | D20: 23.4 | I20: 2.2 | N20: 25.6
A21: AUDAX | D21: 0.9 | H21: 3.1 | I21: 339.8 | K21: 45 | N21: 388.8
A22: AXPO | C22: 161.9 | D22: 808.1 | E22: 9.4 | G22: 364.2 | H22: 184 | I22: 1873.8 | J22: 1010.3 | K22: 2734.5 | M22: 75.7 | N22: 7221.9
A23: BARBO ENERGÃAS RENOVABLES S.A. | G23: 25.9 | N23: 25.9
A24: BASSOLS ENERGIA COMERCIAL,S.L. | G24: 1.9 | I24: 9.2 | N24: 11.1
A25: BBEL CCGT | B25: 785.3 | N25: 785.3
A26: BIOWATT IBERICA S.L | D26: 1.1 | N26: 1.1
A27: BIZCAIA ENERGIA | B27: 786.4 | N27: 786.4
A28: BON PREU SAU | I28: 1.8 | N28: 1.8
A29: BP GAS EUROPE | H29: 54.1 | N29: 54.1
A30: BSG ENERGIA | I30: 14.4 | N30: 14.4
A31: CARNES ESTELLES S.A. | D31: 1.5 | N31: 1.5
A32: CEPSA | B32: 1172.5 | C32: 95.4 | D32: 613 | G32: 61.1 | H32: 65 | I32: 8.1 | K32: 31.4 | M32: 8.8 | N32: 2055.3
A33: CH DUERO | G33: 1.1 | N33: 1.1
A34: COGENERACIÃ“N DE BEGUDA S.A. | D34: 8.9 | N34: 8.9
A35: COGENERADORA BURGALESA | D35: 4.9 | N35: 4.9
A36: COMERCIALIZADOR | I36: 11.7 | N36: 11.7
A37: COMERCIALIZADORA DEL MEDITERRANEO | G37: 0.6 | N37: 0.6
A38: COMPAÃ‘ÃA ESPAÃ‘OLA DE PETROLEOS | D38: 49.4 | N38: 49.4
A39: COMPRAENERGIAPARAGRUPO | H39: 5 | N39: 5
A40: CONECTA2 | I40: 2.8 | N40: 2.8
A41: CONSUMIDOR DIRECTO AYUNTAMIENTO RIVAS | I41: 0.4 | N41: 0.4
A42: CORPORACION ALIMENTARIA GUISSO | D42: 31.4 | N42: 31.4
...
